/var/spool/slurmd/job30363312/slurm_script: line 11: /global/homes/s/sanjeevc/.bashrc: No such file or directory
2024-09-10 19:00:31,037 - distributed.nanny - INFO - Closing Nanny at 'tcp://128.55.80.28:37549'. Reason: failure-to-start-<class 'OSError'>
2024-09-10 19:00:31,039 - distributed.dask_worker - INFO - End worker
ConnectionRefusedError: [Errno 111] Connection refused

The above exception was the direct cause of the following exception:

Traceback (most recent call last):
  File "/global/common/software/nersc/pe/conda-envs/24.1.0/python-3.11/nersc-python/lib/python3.11/site-packages/distributed/comm/core.py", line 342, in connect
    comm = await wait_for(
           ^^^^^^^^^^^^^^^
  File "/global/common/software/nersc/pe/conda-envs/24.1.0/python-3.11/nersc-python/lib/python3.11/site-packages/distributed/utils.py", line 1935, in wait_for
    return await fut
           ^^^^^^^^^
  File "/global/common/software/nersc/pe/conda-envs/24.1.0/python-3.11/nersc-python/lib/python3.11/site-packages/distributed/comm/tcp.py", line 560, in connect
    convert_stream_closed_error(self, e)
  File "/global/common/software/nersc/pe/conda-envs/24.1.0/python-3.11/nersc-python/lib/python3.11/site-packages/distributed/comm/tcp.py", line 140, in convert_stream_closed_error
    raise CommClosedError(f"in {obj}: {exc.__class__.__name__}: {exc}") from exc
distributed.comm.core.CommClosedError: in <distributed.comm.tcp.TCPConnector object at 0x7f4593a38b90>: ConnectionRefusedError: [Errno 111] Connection refused

The above exception was the direct cause of the following exception:

Traceback (most recent call last):
  File "/global/common/software/nersc/pe/conda-envs/24.1.0/python-3.11/nersc-python/lib/python3.11/site-packages/distributed/core.py", line 663, in start
    await wait_for(self.start_unsafe(), timeout=timeout)
  File "/global/common/software/nersc/pe/conda-envs/24.1.0/python-3.11/nersc-python/lib/python3.11/site-packages/distributed/utils.py", line 1935, in wait_for
    return await fut
           ^^^^^^^^^
  File "/global/common/software/nersc/pe/conda-envs/24.1.0/python-3.11/nersc-python/lib/python3.11/site-packages/distributed/nanny.py", line 351, in start_unsafe
    comm = await self.rpc.connect(saddr)
           ^^^^^^^^^^^^^^^^^^^^^^^^^^^^^
  File "/global/common/software/nersc/pe/conda-envs/24.1.0/python-3.11/nersc-python/lib/python3.11/site-packages/distributed/core.py", line 1619, in connect
    return await self._connect(addr=addr, timeout=timeout)
           ^^^^^^^^^^^^^^^^^^^^^^^^^^^^^^^^^^^^^^^^^^^^^^^
  File "/global/common/software/nersc/pe/conda-envs/24.1.0/python-3.11/nersc-python/lib/python3.11/site-packages/distributed/core.py", line 1563, in _connect
    comm = await connect(
           ^^^^^^^^^^^^^^
  File "/global/common/software/nersc/pe/conda-envs/24.1.0/python-3.11/nersc-python/lib/python3.11/site-packages/distributed/comm/core.py", line 368, in connect
    raise OSError(
OSError: Timed out trying to connect to tcp://128.55.64.16:34401 after 30 s

The above exception was the direct cause of the following exception:

Traceback (most recent call last):
  File "<frozen runpy>", line 198, in _run_module_as_main
  File "<frozen runpy>", line 88, in _run_code
  File "/global/common/software/nersc/pe/conda-envs/24.1.0/python-3.11/nersc-python/lib/python3.11/site-packages/distributed/cli/dask_worker.py", line 544, in <module>
    main()  # pragma: no cover
    ^^^^^^
  File "/global/common/software/nersc/pe/conda-envs/24.1.0/python-3.11/nersc-python/lib/python3.11/site-packages/click/core.py", line 1157, in __call__
    return self.main(*args, **kwargs)
           ^^^^^^^^^^^^^^^^^^^^^^^^^^
  File "/global/common/software/nersc/pe/conda-envs/24.1.0/python-3.11/nersc-python/lib/python3.11/site-packages/click/core.py", line 1078, in main
    rv = self.invoke(ctx)
         ^^^^^^^^^^^^^^^^
  File "/global/common/software/nersc/pe/conda-envs/24.1.0/python-3.11/nersc-python/lib/python3.11/site-packages/click/core.py", line 1434, in invoke
    return ctx.invoke(self.callback, **ctx.params)
           ^^^^^^^^^^^^^^^^^^^^^^^^^^^^^^^^^^^^^^^
  File "/global/common/software/nersc/pe/conda-envs/24.1.0/python-3.11/nersc-python/lib/python3.11/site-packages/click/core.py", line 783, in invoke
    return __callback(*args, **kwargs)
           ^^^^^^^^^^^^^^^^^^^^^^^^^^^
  File "/global/common/software/nersc/pe/conda-envs/24.1.0/python-3.11/nersc-python/lib/python3.11/site-packages/distributed/cli/dask_worker.py", line 450, in main
    asyncio_run(run(), loop_factory=get_loop_factory())
  File "/global/common/software/nersc/pe/conda-envs/24.1.0/python-3.11/nersc-python/lib/python3.11/site-packages/distributed/compatibility.py", line 204, in asyncio_run
    return runner.run(main)
           ^^^^^^^^^^^^^^^^
  File "/global/common/software/nersc/pe/conda-envs/24.1.0/python-3.11/nersc-python/lib/python3.11/asyncio/runners.py", line 118, in run
    return self._loop.run_until_complete(task)
           ^^^^^^^^^^^^^^^^^^^^^^^^^^^^^^^^^^^
  File "/global/common/software/nersc/pe/conda-envs/24.1.0/python-3.11/nersc-python/lib/python3.11/asyncio/base_events.py", line 653, in run_until_complete
    return future.result()
           ^^^^^^^^^^^^^^^
  File "/global/common/software/nersc/pe/conda-envs/24.1.0/python-3.11/nersc-python/lib/python3.11/site-packages/distributed/cli/dask_worker.py", line 447, in run
    [task.result() for task in done]
  File "/global/common/software/nersc/pe/conda-envs/24.1.0/python-3.11/nersc-python/lib/python3.11/site-packages/distributed/cli/dask_worker.py", line 447, in <listcomp>
    [task.result() for task in done]
     ^^^^^^^^^^^^^
  File "/global/common/software/nersc/pe/conda-envs/24.1.0/python-3.11/nersc-python/lib/python3.11/site-packages/distributed/cli/dask_worker.py", line 420, in wait_for_nannies_to_finish
    await asyncio.gather(*nannies)
  File "/global/common/software/nersc/pe/conda-envs/24.1.0/python-3.11/nersc-python/lib/python3.11/asyncio/tasks.py", line 694, in _wrap_awaitable
    return (yield from awaitable.__await__())
            ^^^^^^^^^^^^^^^^^^^^^^^^^^^^^^^^
  File "/global/common/software/nersc/pe/conda-envs/24.1.0/python-3.11/nersc-python/lib/python3.11/site-packages/distributed/core.py", line 671, in start
    raise RuntimeError(f"{type(self).__name__} failed to start.") from exc
RuntimeError: Nanny failed to start.
